<?xml version="1.0" ?>
<!-- =================================================================================== -->
<!-- |    This document was autogenerated by xacro from kn800RigidKE.urdf.xacro        | -->
<!-- |    EDITING THIS FILE BY HAND IS NOT RECOMMENDED                                 | -->
<!-- =================================================================================== -->
<robot name="kn800RigidKE">
  <material name="black">
    <color rgba="0.0 0.0 0.0 1.0"/>
  </material>
  <material name="blue">
    <color rgba="0.0 0.0 0.8 1.0"/>
  </material>
  <material name="green">
    <color rgba="0.0 0.8 0.0 1.0"/>
  </material>
  <material name="grey">
    <color rgba="0.2 0.2 0.2 1.0"/>
  </material>
  <material name="orange">
    <color rgba="1.0 0.4235294117647059 0.0392156862745098 1.0"/>
  </material>
  <material name="brown">
    <color rgba="0.8705882352941177 0.8117647058823529 0.7647058823529411 1.0"/>
  </material>
  <material name="red">
    <color rgba="0.8 0.0 0.0 1.0"/>
  </material>
  <material name="white">
    <color rgba="1.0 1.0 1.0 1.0"/>
  </material>
  <material name="aluminium">
    <color rgba="0.5176470588235295 0.5294117647058824 0.5372549019607843 1.0"/>
  </material>
  <link name="world"/>
  <joint name="arm_base_fixed_joint" type="fixed">
    <parent link="world"/>
    <child link="base_link"/>
    <origin rpy="0 3.141592653589793 0" xyz="0 0 2"/>
  </joint>
  <link name="base_link">
    <visual>
      <origin rpy="0 0 0" xyz="0 0 0"/>
      <geometry>
        <mesh filename="package://wisson_description/meshes/kn800Base.STL"/>
      </geometry>
      <material name="aluminium"/>
    </visual>
    <inertial>
      <origin rpy="0 0 0" xyz="0 0 0"/>
      <mass value="0.127"/>
      <inertia ixx="0.00032197" ixy="0.0" ixz="0.0" iyy="0.00032197" iyz="0.0" izz="0.00064284"/>
    </inertial>
  </link>
  <joint name="elongation" type="prismatic">
    <parent link="base_link"/>
    <child link="linear_link_5"/>
    <axis xyz="0 0 1"/>
    <origin rpy="0 0 0" xyz="0 0 0.2"/>
    <limit effort="200" lower="0" upper="0.2" velocity="20"/>
    <dynamics damping="0.7" friction="0.3"/>
  </joint>
  <link name="linear_link_5">
    <visual>
      <geometry>
        <mesh filename="package://wisson_description/meshes/kn800LinearShell.STL"/>
      </geometry>
      <origin rpy="0 0 0" xyz="0 0 0"/>
      <material name="aluminium"/>
    </visual>
    <inertial>
      <origin rpy="0 0 0" xyz="0 0 0"/>
      <mass value="0.08"/>
      <inertia ixx="0.0000528" ixy="0.0" ixz="0.0" iyy=" 0.0000528" iyz="0.0" izz="0.0001055"/>
    </inertial>
  </link>
  <joint name="prismatic_shadow_1" type="prismatic">
    <parent link="base_link"/>
    <child link="linear_link_1"/>
    <axis xyz="0 0 1"/>
    <origin rpy="0 0 0" xyz="0 0 0.04"/>
    <mimic joint="elongation" multiplier="0.2" offset="0"/>
    <limit effort="200" lower="0" upper="0.04" velocity="20"/>
    <dynamics damping="0.7" friction="0.3"/>
  </joint>
  <link name="linear_link_1">
    <visual>
      <geometry>
        <mesh filename="package://wisson_description/meshes/kn800LinearShell.STL"/>
      </geometry>
      <origin rpy="0 0 0" xyz="0 0 0"/>
      <material name="aluminium"/>
    </visual>
    <inertial>
      <origin rpy="0 0 0" xyz="0 0 0"/>
      <mass value="0.08"/>
      <inertia ixx="0.0000528" ixy="0.0" ixz="0.0" iyy=" 0.0000528" iyz="0.0" izz="0.0001055"/>
    </inertial>
  </link>
  <joint name="prismatic_shadow_2" type="prismatic">
    <parent link="linear_link_1"/>
    <child link="linear_link_2"/>
    <axis xyz="0 0 1"/>
    <origin rpy="0 0 0" xyz="0 0 0.04"/>
    <mimic joint="elongation" multiplier="0.2" offset="0"/>
    <limit effort="200" lower="0" upper="0.04" velocity="20"/>
    <dynamics damping="0.7" friction="0.3"/>
  </joint>
  <link name="linear_link_2">
    <visual>
      <geometry>
        <mesh filename="package://wisson_description/meshes/kn800LinearShell.STL"/>
      </geometry>
      <origin rpy="0 0 0" xyz="0 0 0"/>
      <material name="aluminium"/>
    </visual>
    <inertial>
      <origin rpy="0 0 0" xyz="0 0 0"/>
      <mass value="0.08"/>
      <inertia ixx="0.0000528" ixy="0.0" ixz="0.0" iyy=" 0.0000528" iyz="0.0" izz="0.0001055"/>
    </inertial>
  </link>
  <joint name="prismatic_shadow_3" type="prismatic">
    <parent link="linear_link_2"/>
    <child link="linear_link_3"/>
    <axis xyz="0 0 1"/>
    <origin rpy="0 0 0" xyz="0 0 0.04"/>
    <mimic joint="elongation" multiplier="0.2" offset="0"/>
    <limit effort="200" lower="0" upper="0.04" velocity="20"/>
    <dynamics damping="0.7" friction="0.3"/>
  </joint>
  <link name="linear_link_3">
    <visual>
      <geometry>
        <mesh filename="package://wisson_description/meshes/kn800LinearShell.STL"/>
      </geometry>
      <origin rpy="0 0 0" xyz="0 0 0"/>
      <material name="aluminium"/>
    </visual>
    <inertial>
      <origin rpy="0 0 0" xyz="0 0 0"/>
      <mass value="0.08"/>
      <inertia ixx="0.0000528" ixy="0.0" ixz="0.0" iyy=" 0.0000528" iyz="0.0" izz="0.0001055"/>
    </inertial>
  </link>
  <joint name="prismatic_shadow_4" type="prismatic">
    <parent link="linear_link_3"/>
    <child link="linear_link_4"/>
    <axis xyz="0 0 1"/>
    <origin rpy="0 0 0" xyz="0 0 0.04"/>
    <mimic joint="elongation" multiplier="0.2" offset="0"/>
    <limit effort="200" lower="0" upper="0.04" velocity="20"/>
    <dynamics damping="0.7" friction="0.3"/>
  </joint>
  <link name="linear_link_4">
    <visual>
      <geometry>
        <mesh filename="package://wisson_description/meshes/kn800LinearShell.STL"/>
      </geometry>
      <origin rpy="0 0 0" xyz="0 0 0"/>
      <material name="aluminium"/>
    </visual>
    <inertial>
      <origin rpy="0 0 0" xyz="0 0 0"/>
      <mass value="0.08"/>
      <inertia ixx="0.0000528" ixy="0.0" ixz="0.0" iyy=" 0.0000528" iyz="0.0" izz="0.0001055"/>
    </inertial>
  </link>
  <joint name="orientation" type="revolute">
    <parent link="linear_link_5"/>
    <child link="phantom_link_6"/>
    <axis xyz="0 0 1"/>
    <origin rpy="0 0 0" xyz="0 0 0.062"/>
    <limit effort="200" lower="-6.283185307179586" upper="6.283185307179586" velocity="20"/>
    <dynamics damping="0.7" friction="0.3"/>
  </joint>
  <link name="phantom_link_6">
    <visual>
      <geometry>
        <cylinder length="0.0001" radius="0.0001"/>
      </geometry>
      <origin rpy="0 0 0" xyz="0 0 0"/>
      <material name="aluminium"/>
    </visual>
    <inertial>
      <origin rpy="0 0 0" xyz="0 0 0"/>
      <mass value="0.08"/>
      <inertia ixx="0.0000528" ixy="0.0" ixz="0.0" iyy=" 0.0000528" iyz="0.0" izz="0.0001055"/>
    </inertial>
  </link>
  <joint name="bending" type="revolute">
    <parent link="phantom_link_6"/>
    <child link="phantom_link_999"/>
    <axis xyz="0 1 0"/>
    <origin rpy="0 0 0" xyz="0 0 0"/>
    <limit effort="200" lower="-3.141592653589793" upper="3.141592653589793" velocity="20"/>
    <dynamics damping="0.7" friction="0.3"/>
  </joint>
  <link name="phantom_link_999">
    <visual>
      <geometry>
        <cylinder length="0.0001" radius="0.0001"/>
      </geometry>
      <origin rpy="0 0 0" xyz="0 0 0"/>
      <material name="aluminium"/>
    </visual>
    <inertial>
      <origin rpy="0 0 0" xyz="0 0 0"/>
      <mass value="0.08"/>
      <inertia ixx="0.0000528" ixy="0.0" ixz="0.0" iyy=" 0.0000528" iyz="0.0" izz="0.0001055"/>
    </inertial>
  </link>
  <joint name="bending_shadow_1" type="revolute">
    <parent link="phantom_link_6"/>
    <child link="phantom_link_7"/>
    <axis xyz="0 1 0"/>
    <origin rpy="0 0 0" xyz="0 0 0"/>
    <mimic joint="bending" multiplier="0.16666666666666666" offset="0"/>
    <limit effort="200" lower="-0.5235987755982988" upper="0.5235987755982988" velocity="20"/>
    <dynamics damping="0.7" friction="0.3"/>
  </joint>
  <link name="phantom_link_7">
    <visual>
      <geometry>
        <cylinder length="0.0001" radius="0.0001"/>
      </geometry>
      <origin rpy="0 0 0" xyz="0 0 0"/>
      <material name="aluminium"/>
    </visual>
    <inertial>
      <origin rpy="0 0 0" xyz="0 0 0"/>
      <mass value="0.08"/>
      <inertia ixx="0.0000528" ixy="0.0" ixz="0.0" iyy=" 0.0000528" iyz="0.0" izz="0.0001055"/>
    </inertial>
  </link>
  <joint name="orientation_shadow_1_2" type="revolute">
    <parent link="phantom_link_7"/>
    <child link="rotary_link_6"/>
    <axis xyz="0 0 1"/>
    <origin rpy="0 0 0" xyz="0 0 0"/>
    <mimic joint="orientation" multiplier="-1" offset="0"/>
    <limit effort="200" lower="-6.283185307179586" upper="6.283185307179586" velocity="20"/>
    <dynamics damping="0.7" friction="0.3"/>
  </joint>
  <link name="rotary_link_6">
    <visual>
      <geometry>
        <mesh filename="package://wisson_description/meshes/kn800BendingShell.STL"/>
      </geometry>
      <origin rpy="0 0 0" xyz="0 0 0.062"/>
      <material name="aluminium"/>
    </visual>
    <inertial>
      <origin rpy="0 0 0" xyz="0 0 0.062"/>
      <mass value="0.08"/>
      <inertia ixx="0.0000528" ixy="0.0" ixz="0.0" iyy=" 0.0000528" iyz="0.0" izz="0.0001055"/>
    </inertial>
  </link>
  <joint name="orientation_shadow_2_1" type="revolute">
    <parent link="rotary_link_6"/>
    <child link="phantom_link_8"/>
    <axis xyz="0 0 1"/>
    <origin rpy="0 0 0" xyz="0 0 0.124"/>
    <mimic joint="orientation" multiplier="1" offset="0"/>
    <limit effort="200" lower="-6.283185307179586" upper="6.283185307179586" velocity="20"/>
    <dynamics damping="0.7" friction="0.3"/>
  </joint>
  <link name="phantom_link_8">
    <visual>
      <geometry>
        <cylinder length="0.0001" radius="0.0001"/>
      </geometry>
      <origin rpy="0 0 0" xyz="0 0 0"/>
      <material name="aluminium"/>
    </visual>
    <inertial>
      <origin rpy="0 0 0" xyz="0 0 0"/>
      <mass value="0.08"/>
      <inertia ixx="0.0000528" ixy="0.0" ixz="0.0" iyy=" 0.0000528" iyz="0.0" izz="0.0001055"/>
    </inertial>
  </link>
  <joint name="bending_shadow_2" type="revolute">
    <parent link="phantom_link_8"/>
    <child link="phantom_link_9"/>
    <axis xyz="0 1 0"/>
    <origin rpy="0 0 0" xyz="0 0 0"/>
    <mimic joint="bending" multiplier="0.16666666666666666" offset="0"/>
    <limit effort="200" lower="-0.5235987755982988" upper="0.5235987755982988" velocity="20"/>
    <dynamics damping="0.7" friction="0.3"/>
  </joint>
  <link name="phantom_link_9">
    <visual>
      <geometry>
        <cylinder length="0.0001" radius="0.0001"/>
      </geometry>
      <origin rpy="0 0 0" xyz="0 0 0"/>
      <material name="aluminium"/>
    </visual>
    <inertial>
      <origin rpy="0 0 0" xyz="0 0 0"/>
      <mass value="0.08"/>
      <inertia ixx="0.0000528" ixy="0.0" ixz="0.0" iyy=" 0.0000528" iyz="0.0" izz="0.0001055"/>
    </inertial>
  </link>
  <joint name="orientation_shadow_2_2" type="revolute">
    <parent link="phantom_link_9"/>
    <child link="rotary_link_7"/>
    <axis xyz="0 0 1"/>
    <origin rpy="0 0 0" xyz="0 0 0"/>
    <mimic joint="orientation" multiplier="-1" offset="0"/>
    <limit effort="200" lower="-6.283185307179586" upper="6.283185307179586" velocity="20"/>
    <dynamics damping="0.7" friction="0.3"/>
  </joint>
  <link name="rotary_link_7">
    <visual>
      <geometry>
        <mesh filename="package://wisson_description/meshes/kn800BendingShell.STL"/>
      </geometry>
      <origin rpy="0 0 0" xyz="0 0 0.062"/>
      <material name="aluminium"/>
    </visual>
    <inertial>
      <origin rpy="0 0 0" xyz="0 0 0.062"/>
      <mass value="0.08"/>
      <inertia ixx="0.0000528" ixy="0.0" ixz="0.0" iyy=" 0.0000528" iyz="0.0" izz="0.0001055"/>
    </inertial>
  </link>
  <joint name="orientation_shadow_3_1" type="revolute">
    <parent link="rotary_link_7"/>
    <child link="phantom_link_10"/>
    <axis xyz="0 0 1"/>
    <origin rpy="0 0 0" xyz="0 0 0.124"/>
    <mimic joint="orientation" multiplier="1" offset="0"/>
    <limit effort="200" lower="-6.283185307179586" upper="6.283185307179586" velocity="20"/>
    <dynamics damping="0.7" friction="0.3"/>
  </joint>
  <link name="phantom_link_10">
    <visual>
      <geometry>
        <cylinder length="0.0001" radius="0.0001"/>
      </geometry>
      <origin rpy="0 0 0" xyz="0 0 0"/>
      <material name="aluminium"/>
    </visual>
    <inertial>
      <origin rpy="0 0 0" xyz="0 0 0"/>
      <mass value="0.08"/>
      <inertia ixx="0.0000528" ixy="0.0" ixz="0.0" iyy=" 0.0000528" iyz="0.0" izz="0.0001055"/>
    </inertial>
  </link>
  <joint name="bending_shadow_3" type="revolute">
    <parent link="phantom_link_10"/>
    <child link="phantom_link_11"/>
    <axis xyz="0 1 0"/>
    <origin rpy="0 0 0" xyz="0 0 0"/>
    <mimic joint="bending" multiplier="0.16666666666666666" offset="0"/>
    <limit effort="200" lower="-0.5235987755982988" upper="0.5235987755982988" velocity="20"/>
    <dynamics damping="0.7" friction="0.3"/>
  </joint>
  <link name="phantom_link_11">
    <visual>
      <geometry>
        <cylinder length="0.0001" radius="0.0001"/>
      </geometry>
      <origin rpy="0 0 0" xyz="0 0 0"/>
      <material name="aluminium"/>
    </visual>
    <inertial>
      <origin rpy="0 0 0" xyz="0 0 0"/>
      <mass value="0.08"/>
      <inertia ixx="0.0000528" ixy="0.0" ixz="0.0" iyy=" 0.0000528" iyz="0.0" izz="0.0001055"/>
    </inertial>
  </link>
  <joint name="orientation_shadow_3_2" type="revolute">
    <parent link="phantom_link_11"/>
    <child link="rotary_link_8"/>
    <axis xyz="0 0 1"/>
    <origin rpy="0 0 0" xyz="0 0 0"/>
    <mimic joint="orientation" multiplier="-1" offset="0"/>
    <limit effort="200" lower="-6.283185307179586" upper="6.283185307179586" velocity="20"/>
    <dynamics damping="0.7" friction="0.3"/>
  </joint>
  <link name="rotary_link_8">
    <visual>
      <geometry>
        <mesh filename="package://wisson_description/meshes/kn800BendingShell.STL"/>
      </geometry>
      <origin rpy="0 0 0" xyz="0 0 0.062"/>
      <material name="aluminium"/>
    </visual>
    <inertial>
      <origin rpy="0 0 0" xyz="0 0 0.062"/>
      <mass value="0.08"/>
      <inertia ixx="0.0000528" ixy="0.0" ixz="0.0" iyy=" 0.0000528" iyz="0.0" izz="0.0001055"/>
    </inertial>
  </link>
  <joint name="orientation_shadow_4_1" type="revolute">
    <parent link="rotary_link_8"/>
    <child link="phantom_link_12"/>
    <axis xyz="0 0 1"/>
    <origin rpy="0 0 0" xyz="0 0 0.124"/>
    <mimic joint="orientation" multiplier="1" offset="0"/>
    <limit effort="200" lower="-6.283185307179586" upper="6.283185307179586" velocity="20"/>
    <dynamics damping="0.7" friction="0.3"/>
  </joint>
  <link name="phantom_link_12">
    <visual>
      <geometry>
        <cylinder length="0.0001" radius="0.0001"/>
      </geometry>
      <origin rpy="0 0 0" xyz="0 0 0"/>
      <material name="aluminium"/>
    </visual>
    <inertial>
      <origin rpy="0 0 0" xyz="0 0 0"/>
      <mass value="0.08"/>
      <inertia ixx="0.0000528" ixy="0.0" ixz="0.0" iyy=" 0.0000528" iyz="0.0" izz="0.0001055"/>
    </inertial>
  </link>
  <joint name="bending_shadow_4" type="revolute">
    <parent link="phantom_link_12"/>
    <child link="phantom_link_13"/>
    <axis xyz="0 1 0"/>
    <origin rpy="0 0 0" xyz="0 0 0"/>
    <mimic joint="bending" multiplier="0.16666666666666666" offset="0"/>
    <limit effort="200" lower="-0.5235987755982988" upper="0.5235987755982988" velocity="20"/>
    <dynamics damping="0.7" friction="0.3"/>
  </joint>
  <link name="phantom_link_13">
    <visual>
      <geometry>
        <cylinder length="0.0001" radius="0.0001"/>
      </geometry>
      <origin rpy="0 0 0" xyz="0 0 0"/>
      <material name="aluminium"/>
    </visual>
    <inertial>
      <origin rpy="0 0 0" xyz="0 0 0"/>
      <mass value="0.08"/>
      <inertia ixx="0.0000528" ixy="0.0" ixz="0.0" iyy=" 0.0000528" iyz="0.0" izz="0.0001055"/>
    </inertial>
  </link>
  <joint name="orientation_shadow_4_2" type="revolute">
    <parent link="phantom_link_13"/>
    <child link="rotary_link_9"/>
    <axis xyz="0 0 1"/>
    <origin rpy="0 0 0" xyz="0 0 0"/>
    <mimic joint="orientation" multiplier="-1" offset="0"/>
    <limit effort="200" lower="-6.283185307179586" upper="6.283185307179586" velocity="20"/>
    <dynamics damping="0.7" friction="0.3"/>
  </joint>
  <link name="rotary_link_9">
    <visual>
      <geometry>
        <mesh filename="package://wisson_description/meshes/kn800BendingShell.STL"/>
      </geometry>
      <origin rpy="0 0 0" xyz="0 0 0.062"/>
      <material name="aluminium"/>
    </visual>
    <inertial>
      <origin rpy="0 0 0" xyz="0 0 0.062"/>
      <mass value="0.08"/>
      <inertia ixx="0.0000528" ixy="0.0" ixz="0.0" iyy=" 0.0000528" iyz="0.0" izz="0.0001055"/>
    </inertial>
  </link>
  <joint name="orientation_shadow_5_1" type="revolute">
    <parent link="rotary_link_9"/>
    <child link="phantom_link_14"/>
    <axis xyz="0 0 1"/>
    <origin rpy="0 0 0" xyz="0 0 0.124"/>
    <mimic joint="orientation" multiplier="1" offset="0"/>
    <limit effort="200" lower="-6.283185307179586" upper="6.283185307179586" velocity="20"/>
    <dynamics damping="0.7" friction="0.3"/>
  </joint>
  <link name="phantom_link_14">
    <visual>
      <geometry>
        <cylinder length="0.0001" radius="0.0001"/>
      </geometry>
      <origin rpy="0 0 0" xyz="0 0 0"/>
      <material name="aluminium"/>
    </visual>
    <inertial>
      <origin rpy="0 0 0" xyz="0 0 0"/>
      <mass value="0.08"/>
      <inertia ixx="0.0000528" ixy="0.0" ixz="0.0" iyy=" 0.0000528" iyz="0.0" izz="0.0001055"/>
    </inertial>
  </link>
  <joint name="bending_shadow_5" type="revolute">
    <parent link="phantom_link_14"/>
    <child link="phantom_link_15"/>
    <axis xyz="0 1 0"/>
    <origin rpy="0 0 0" xyz="0 0 0"/>
    <mimic joint="bending" multiplier="0.16666666666666666" offset="0"/>
    <limit effort="200" lower="-0.5235987755982988" upper="0.5235987755982988" velocity="20"/>
    <dynamics damping="0.7" friction="0.3"/>
  </joint>
  <link name="phantom_link_15">
    <visual>
      <geometry>
        <cylinder length="0.0001" radius="0.0001"/>
      </geometry>
      <origin rpy="0 0 0" xyz="0 0 0"/>
      <material name="aluminium"/>
    </visual>
    <inertial>
      <origin rpy="0 0 0" xyz="0 0 0"/>
      <mass value="0.08"/>
      <inertia ixx="0.0000528" ixy="0.0" ixz="0.0" iyy=" 0.0000528" iyz="0.0" izz="0.0001055"/>
    </inertial>
  </link>
  <joint name="orientation_shadow_5_2" type="revolute">
    <parent link="phantom_link_15"/>
    <child link="rotary_link_10"/>
    <axis xyz="0 0 1"/>
    <origin rpy="0 0 0" xyz="0 0 0"/>
    <mimic joint="orientation" multiplier="-1" offset="0"/>
    <limit effort="200" lower="-6.283185307179586" upper="6.283185307179586" velocity="20"/>
    <dynamics damping="0.7" friction="0.3"/>
  </joint>
  <link name="rotary_link_10">
    <visual>
      <geometry>
        <mesh filename="package://wisson_description/meshes/kn800BendingShell.STL"/>
      </geometry>
      <origin rpy="0 0 0" xyz="0 0 0.062"/>
      <material name="aluminium"/>
    </visual>
    <inertial>
      <origin rpy="0 0 0" xyz="0 0 0.062"/>
      <mass value="0.08"/>
      <inertia ixx="0.0000528" ixy="0.0" ixz="0.0" iyy=" 0.0000528" iyz="0.0" izz="0.0001055"/>
    </inertial>
  </link>
  <joint name="orientation_shadow_6_1" type="revolute">
    <parent link="rotary_link_10"/>
    <child link="phantom_link_16"/>
    <axis xyz="0 0 1"/>
    <origin rpy="0 0 0" xyz="0 0 0.124"/>
    <mimic joint="orientation" multiplier="1" offset="0"/>
    <limit effort="200" lower="-6.283185307179586" upper="6.283185307179586" velocity="20"/>
    <dynamics damping="0.7" friction="0.3"/>
  </joint>
  <link name="phantom_link_16">
    <visual>
      <geometry>
        <cylinder length="0.0001" radius="0.0001"/>
      </geometry>
      <origin rpy="0 0 0" xyz="0 0 0"/>
      <material name="aluminium"/>
    </visual>
    <inertial>
      <origin rpy="0 0 0" xyz="0 0 0"/>
      <mass value="0.08"/>
      <inertia ixx="0.0000528" ixy="0.0" ixz="0.0" iyy=" 0.0000528" iyz="0.0" izz="0.0001055"/>
    </inertial>
  </link>
  <joint name="bending_shadow_6" type="revolute">
    <parent link="phantom_link_16"/>
    <child link="phantom_link_17"/>
    <axis xyz="0 1 0"/>
    <origin rpy="0 0 0" xyz="0 0 0"/>
    <mimic joint="bending" multiplier="0.16666666666666666" offset="0"/>
    <limit effort="200" lower="-0.5235987755982988" upper="0.5235987755982988" velocity="20"/>
    <dynamics damping="0.7" friction="0.3"/>
  </joint>
  <link name="phantom_link_17">
    <visual>
      <geometry>
        <cylinder length="0.0001" radius="0.0001"/>
      </geometry>
      <origin rpy="0 0 0" xyz="0 0 0"/>
      <material name="aluminium"/>
    </visual>
    <inertial>
      <origin rpy="0 0 0" xyz="0 0 0"/>
      <mass value="0.08"/>
      <inertia ixx="0.0000528" ixy="0.0" ixz="0.0" iyy=" 0.0000528" iyz="0.0" izz="0.0001055"/>
    </inertial>
  </link>
  <joint name="orientation_shadow_6_2" type="revolute">
    <parent link="phantom_link_17"/>
    <child link="link_BendingEnd"/>
    <axis xyz="0 0 1"/>
    <origin rpy="0 0 0" xyz="0 0 0.062"/>
    <mimic joint="orientation" multiplier="-1" offset="0"/>
    <limit effort="200" lower="-6.283185307179586" upper="6.283185307179586" velocity="20"/>
    <dynamics damping="0.7" friction="0.3"/>
  </joint>
  <link name="link_BendingEnd">
    <visual>
      <origin rpy="0 0 0" xyz="0 0 0"/>
      <geometry>
        <mesh filename="package://wisson_description/meshes/kn800BendingShellEnd.STL"/>
      </geometry>
      <material name="aluminium"/>
    </visual>
    <inertial>
      <origin rpy="0 0 0" xyz="0 0 0"/>
      <mass value="0.127"/>
      <inertia ixx="0.00032197" ixy="0.0" ixz="0.0" iyy="0.00032197" iyz="0.0" izz="0.00064284"/>
    </inertial>
  </link>
  <joint name="gripperBaseFixed" type="fixed">
    <parent link="link_BendingEnd"/>
    <child link="link_gripper_base"/>
    <origin rpy="0 0 0" xyz="0 0 0"/>
  </joint>
  <link name="link_gripper_base">
    <visual>
      <origin rpy="0 0 0" xyz="0 0 0"/>
      <geometry>
        <mesh filename="package://wisson_description/meshes/kn800GripperBase.STL"/>
      </geometry>
      <material name="aluminium"/>
    </visual>
    <inertial>
      <origin rpy="0 0 0" xyz="0 0 0"/>
      <mass value="0.127"/>
      <inertia ixx="0.00032197" ixy="0.0" ixz="0.0" iyy="0.00032197" iyz="0.0" izz="0.00064284"/>
    </inertial>
  </link>
  <joint name="grasp" type="revolute">
    <parent link="link_gripper_base"/>
    <child link="finger_1"/>
    <origin rpy="0 0 0" xyz="0.037 0.0 0.118"/>
    <axis xyz="0 -1 0"/>
    <limit effort="200" lower="-0.18849555921538758" upper="1.2566370614359172" velocity="20"/>
    <dynamics damping="0.7" friction="0.3"/>
  </joint>
  <link name="finger_1">
    <visual>
      <origin rpy="0 0 0" xyz="0 0 0"/>
      <geometry>
        <mesh filename="package://wisson_description/meshes/kn800GripperFinger.STL"/>
      </geometry>
      <material name="aluminium"/>
    </visual>
    <inertial>
      <origin rpy="0 0 0" xyz="0 0 0"/>
      <mass value="0.127"/>
      <inertia ixx="0.00032197" ixy="0.0" ixz="0.0" iyy="0.00032197" iyz="0.0" izz="0.00064284"/>
    </inertial>
  </link>
  <joint name="grasp2" type="revolute">
    <parent link="link_gripper_base"/>
    <child link="finger_2"/>
    <origin rpy="0 0 2.0943951023931953" xyz="-0.018499999999999992 0.03204293994002423 0.12"/>
    <axis xyz="0 -1 0"/>
    <mimic joint="grasp" multiplier="1" offset="0"/>
    <limit effort="200" lower="-0.18849555921538758" upper="1.2566370614359172" velocity="20"/>
    <dynamics damping="0.7" friction="0.3"/>
  </joint>
  <link name="finger_2">
    <visual>
      <origin rpy="0 0 0" xyz="0 0 0"/>
      <geometry>
        <mesh filename="package://wisson_description/meshes/kn800GripperFinger.STL"/>
      </geometry>
      <material name="aluminium"/>
    </visual>
    <inertial>
      <origin rpy="0 0 0" xyz="0 0 0"/>
      <mass value="0.127"/>
      <inertia ixx="0.00032197" ixy="0.0" ixz="0.0" iyy="0.00032197" iyz="0.0" izz="0.00064284"/>
    </inertial>
  </link>
  <joint name="grasp3" type="revolute">
    <parent link="link_gripper_base"/>
    <child link="finger_3"/>
    <origin rpy="0 0 4.1887902047863905" xyz="-0.018500000000000016 -0.03204293994002422 0.12"/>
    <axis xyz="0 -1 0"/>
    <mimic joint="grasp" multiplier="1" offset="0"/>
    <limit effort="200" lower="-0.18849555921538758" upper="1.2566370614359172" velocity="20"/>
    <dynamics damping="0.7" friction="0.3"/>
  </joint>
  <link name="finger_3">
    <visual>
      <origin rpy="0 0 0" xyz="0 0 0"/>
      <geometry>
        <mesh filename="package://wisson_description/meshes/kn800GripperFinger.STL"/>
      </geometry>
      <material name="aluminium"/>
    </visual>
    <inertial>
      <origin rpy="0 0 0" xyz="0 0 0"/>
      <mass value="0.127"/>
      <inertia ixx="0.00032197" ixy="0.0" ixz="0.0" iyy="0.00032197" iyz="0.0" izz="0.00064284"/>
    </inertial>
  </link>
</robot>

